Workbook

Sheet METHODES_PERFUSION
A1: Méthodes de perfusion — paramètres généraux
A2: Base de paramètres lue par le logiciel. Les scénarios ne sont pas saisis ici : ils seront générés dynamiquement par le moteur inversé.
A3: methode_id | B3: libelle | C3: mode | D3: volume_ml | E3: duree_h_defaut | F3: location_jour | G3: dm_captif | H3: dm_unique | I3: passages_ide_par_jour_defaut | J3: frequences_possibles | K3: contexte_defaut | L3: commentaire
A4: POCHE_VOL_CONT | B4: Poche en pompe volumétrique classique | C4: continu | D4: variable | E4: 24 | F4: non | G4: non | H4: oui | I4: 1 | J4: q24/q12/q8/q6 | K4: HOSPITALIER | L4: Intra-hospitalier uniquement dans le modèle ; volume selon moteur.
A5: PSE_48_CONT | B5: PSE 48 mL | C5: continu | D5: 48 | E5: variable | F5: non | G5: non | H5: oui | I5: variable | J5: q24/q12/q8/q6 | K5: HOSPITALIER | L5: PSE 48 mL intra-hospitalier ; changement selon stabilité.
A6: PSE_24_HAD_CONT | B6: PSE HAD 24 mL | C6: continu | D6: 24 | E6: variable | F6: oui | G6: non | H6: oui | I6: variable | J6: q24/q12/q8/q6 | K6: HAD | L6: Pousse-seringue électrique HAD ; location par jour ; concentration calculée sur 24 mL.
A7: RYTHMIC_CONT | B7: Pompe Rythmic / Micrel | C7: continu | D7: 100 ou 200 | E7: 24 | F7: oui | G7: oui | H7: non | I7: 1 | J7: q24/q12 | K7: HAD | L7: HAD uniquement ; location par jour + DM captif.
A8: ANAPA_CONT | B8: ANAPA | C8: continu | D8: 250 | E8: 12 | F8: non | G8: non | H8: oui | I8: 2 | J8: q12 | K8: HOSPITALIER/HAD | L8: DM unique. | ACV/poids diffuseur unifies (0,3 kgCO2e / 43 g).
A9: NEOPUMP_CONT | B9: NEOPUMP | C9: continu | D9: 500 | E9: 12 ou 24 | F9: non | G9: non | H9: oui | I9: 1 ou 2 | J9: q24/q12 | K9: HOSPITALIER/HAD | L9: DM unique. | ACV/poids diffuseur unifies (0,3 kgCO2e / 43 g).
A10: POCHE_DISCONT | B10: Poche classique discontinue | C10: discontinu | D10: variable | E10: administration courte | F10: non | G10: non | H10: oui | I10: nb administrations/j | J10: x1 à x6/j | K10: HOSPITALIER/HAD | L10: Discontinu : poche classique uniquement.
A11: ELASTOMERE_GENERIC | B11: Diffuseur élastomère générique | C11: continu | D11: 100/150/250/500 | E11: 12 ou 24 | F11: non | G11: non | H11: oui | I11: 1 ou 2 | J11: q24/q12 | K11: HOSPITALIER/HAD | L11: Proxy coût/CO₂ : diffuseur élastomère générique assimilé à NEOPUMP 250/500 mL selon volume, à remplacer par données fournisseur si disponibles. | ACV/poids diffuseur unifies (0,3 kgCO2e / 43 g).

Sheet MATERIEL_PAR_METHODE
A1: Matériel par méthode — panier de consommables
A2: Chaque ligne représente un item consommé par administration/perfusion. Le moteur multiplie par le nombre réel de perfusions/changements par jour.
A3: methode_id | B3: item_id | C3: item_libelle | D3: categorie | E3: quantite_par_perfusion | F3: inclus_dans_dm_captif | G3: a_compter | H3: commentaire
A4: POCHE_VOL_CONT | B4: POCHE_NACL_G5_VARIABLE | C4: Poche NaCl/G5 volume selon moteur | D4: contenant/solvant final | E4: 1 | F4: non | G4: oui | H4: Continu : poche en pompe volumétrique classique ; le moteur choisit le plus petit volume compatible par solvant.
A5: POCHE_VOL_CONT | B5: TUBULURE_POMPE_VOL | C5: Tubulure pompe volumétrique | D5: administration | E5: 1 | F5: non | G5: oui | H5: Tubulure spécifique pompe volumétrique.
A6: POCHE_VOL_CONT | B6: PROLONGATEUR_STANDARD | C6: Prolongateur standard | D6: administration | E6: 1 | F6: non | G6: à confirmer | H6: Selon montage local ; inclus si paramètre inclure_items_a_confirmer = 1.
A7: POCHE_VOL_CONT | B7: RINCAGE_NACL_10ML | C7: Rinçage NaCl 10 mL | D7: rinçage | E7: 1 | F7: non | G7: oui | H7: Avant/après selon protocole.
A8: POCHE_VOL_CONT | B8: ETIQUETTE | C8: Étiquette préparation | D8: traçabilité | E8: 1 | F8: non | G8: oui | H8: Par administration préparée.
A9: PSE_48_CONT | B9: SERINGUE_PP_50ML | C9: Seringue PP 50 mL | D9: contenant | E9: 1 | F9: non | G9: oui | H9: PSE 48 mL intra-hospitalier.
A10: PSE_48_CONT | B10: POCHE_NACL_G5_VARIABLE | C10: Poche NaCl/G5 pour dilution/remplissage | D10: solvant final | E10: 1 | F10: non | G10: oui | H10: Le moteur choisit la plus petite poche possible compatible avec la concentration.
A11: PSE_48_CONT | B11: PROLONGATEUR_PSE | C11: Prolongateur PSE | D11: administration | E11: 1 | F11: non | G11: oui | H11: Tubulure/prolongateur spécifique PSE.
A12: PSE_48_CONT | B12: RINCAGE_NACL_10ML | C12: Rinçage NaCl 10 mL | D12: rinçage | E12: 1 | F12: non | G12: oui | H12: Par changement de seringue.
A13: PSE_48_CONT | B13: ETIQUETTE | C13: Étiquette préparation | D13: traçabilité | E13: 1 | F13: non | G13: oui | H13: Par seringue préparée.
A14: PSE_24_HAD_CONT | B14: SERINGUE_PP_24ML | C14: Seringue PP 24 mL | D14: contenant | E14: 1 | F14: non | G14: oui | H14: PSE HAD 24 mL ; continu en HAD uniquement.
A15: PSE_24_HAD_CONT | B15: POCHE_NACL_G5_VARIABLE | C15: Poche NaCl/G5 pour dilution/remplissage | D15: solvant final | E15: 1 | F15: non | G15: oui | H15: Le moteur choisit la plus petite poche possible compatible avec la concentration.
... A40: ELASTOMERE_GENERIC | B40: ETIQUETTE | C40: Étiquette préparation | D40: traçabilité | E40: 1 | F40: non | G40: oui | H40: Par dispositif préparé.

Sheet FACTEURS_ITEMS
A1: Facteurs coût et CO₂ des consommables
A2: Compléter les coûts unitaires, kgCO₂e unitaires et poids. Ces valeurs seront utilisées pour calculer coût/CO₂ par jour et par traitement.
A3: item_id | B3: item_libelle | C3: cout_unitaire_eur | D3: kgco2e_unitaire | E3: poids_g | F3: type_dechet | G3: source_cout | H3: source_co2 | I3: niveau_incertitude | J3: commentaire
A4: POCHE_NACL_G5_50ML | B4: Poche NaCl/G5 50 mL | C4: =0.5*1.02 -> 0.51 | D4: 0.201 | E4: 8 | F4: DASRI | G4: Copilote | H4: Carebone / LLM | I4: moyen
A5: POCHE_NACL_G5_100ML | B5: Poche NaCl/G5 100 mL | C5: =0.53*1.02 -> 0.5406 | D5: 0.278 | E5: 10 | F5: DASRI | G5: Copilote | H5: Carebone / LLM | I5: moyen
A6: POCHE_NACL_G5_250ML | B6: Poche NaCl/G5 250 mL | C6: =0.697*1.021 -> 0.711637 | D6: 0.507 | E6: 14 | F6: DASRI | G6: Copilote | H6: Carebone / LLM | I6: moyen
A7: POCHE_NACL_G5_500ML | B7: Poche NaCl/G5 500 mL | C7: =0.714*1.021 -> 0.728994 | D7: 0.889 | E7: 20 | F7: DASRI | G7: Copilote | H7: Carebone / LLM | I7: moyen
A8: SERINGUE_PP_24ML | B8: Seringue PP 24 mL | C8: =0.176*1.2 -> 0.2112 | D8: 0.069 | E8: 12 | F8: DASRI | G8: Copilote | H8: Carebone / LLM | I8: moyen | J8: Utilisée aussi comme proxy de seringue de reconstitution par défaut dans l'onglet ACV ATB ; à adapter si seringue 10/20 mL réelle.
A9: SERINGUE_PP_50ML | B9: Seringue PP 50 mL | C9: =0.8435*1.2 -> 1.0122 | D9: 0.136 | E9: 18 | F9: DASRI | G9: Copilote | H9: Carebone / LLM | I9: moyen
A10: TUBULURE_POMPE_VOL | B10: Tubulure pompe volumétrique | C10: =9.8*1.2 -> 11.76 | D10: 0.241 | E10: 55 | F10: DASRI | G10: Copilote | H10: Carebone / LLM | I10: élevé | J10: Poste ACV dominant (0,241 kgCO₂e/changement). Source LLM — à revalider en priorité auprès du fournisseur ou via ACV de référence plastique médical.
A11: PROLONGATEUR_STANDARD | B11: Prolongateur standard | C11: =0.3926*1.2 -> 0.47112 | D11: 0.079 | E11: 8 | F11: DASRI | G11: Copilote | H11: Carebone / LLM | I11: élevé | J11: Source LLM. À revalider fournisseur. Faible poids (8 g) donc impact limité, mais utilisé sur toutes les méthodes poche.
A12: PROLONGATEUR_PSE | B12: Prolongateur PSE | C12: =0.2759*1.2 -> 0.33108 | D12: 0.055 | E12: 10 | F12: DASRI | G12: Copilote | H12: Carebone / LLM | I12: élevé | J12: Source LLM. À revalider fournisseur.
A13: PERFUSEUR_STANDARD | B13: Perfuseur standard | C13: =0.3876*1.2 -> 0.46512 | D13: 0.182 | E13: 35 | F13: DASRI | G13: Copilote | H13: Carebone / LLM | I13: élevé | J13: Poste ACV significatif (0,182 kgCO₂e). Source LLM — à revalider fournisseur.
A14: RESERVOIR_RYTHMIC_200ML | B14: Poche/réservoir Rythmic avec tubulure 200 mL | C14: =16.97*1.2 -> 20.364 | D14: 0.209 | E14: 50 | F14: DASRI | G14: Copilote | H14: Carebone / LLM | I14: faible | J14: À renseigner seulement si non inclus dans DM captif/location
A15: RESERVOIR_RYTHMIC_100ML | B15: Poche/réservoir Rythmic avec tubulure 100 mL | C15: =16*1.2 -> 19.2 | D15: =0.209-0.037/2 -> 0.1905 | E15: 50 | F15: DASRI | G15: Copilote | H15: Carebone / LLM | I15: faible | J15: À renseigner seulement si non inclus dans DM captif/location
A16: DISPOSITIF_ANAPA_250 | B16: ANAPA 250 mL | C16: =36.41*1.2 -> 43.692 | D16: 0.3 | E16: 43 | F16: DASRI | G16: Copilote | H16: ACV unifiée diffuseurs (base NEOPUMP 500) | I16: moyen | J16: ACV et poids unifies pour tous les diffuseurs (0.3 kgCO2e, 43 g) : valeurs par marque/volume = estimations LLM non differenciables. Cout d'achat conserve par marque. Anciennes valeurs : 0.668 kgCO2e / 150 g. A remplacer par pesee/ACV fournisseur.
A17: NEOPUMP_500 | B17: NEOPUMP 500 mL | C17: =11.96*1.2 -> 14.352 | D17: 0.3 | E17: 43 | F17: DASRI | G17: Copilote | H17: ACV unifiée diffuseurs (base NEOPUMP 500) | I17: moyen | J17: ACV et poids unifies pour tous les diffuseurs (0.3 kgCO2e, 43 g) : valeurs par marque/volume = estimations LLM non differenciables. Cout d'achat conserve par marque. Anciennes valeurs : 0.3 kgCO2e / 43 g. A remplacer par pesee/ACV fournisseur.
A18: NEOPUMP_250 | B18: NEOPUMP 250 mL | C18: =11.96*1.2 -> 14.352 | D18: 0.3 | E18: 43 | F18: DASRI | G18: Estimation | H18: ACV unifiée diffuseurs (base NEOPUMP 500) | I18: moyen | J18: ACV et poids unifies pour tous les diffuseurs (0.3 kgCO2e, 43 g) : valeurs par marque/volume = estimations LLM non differenciables. Cout d'achat conserve par marque. Anciennes valeurs : 0.242 kgCO2e / 43 g. A remplacer par pesee/ACV fournisseur.
A19: RINCAGE_NACL_10ML | B19: Rinçage NaCl 10 mL | C19: =0.3 -> 0.3 | D19: 0.047 | E19: 8 | F19: DASRI | G19: Copilote | H19: Carebone / LLM | I19: moyen | J19: Seringue préremplie ou seringue + ampoule selon pratique
A20: COMPRESSE_ANTISEPTIQUE | B20: Compresse + antiseptique | C20: =0.1 -> 0.1 | D20: 0.055 | E20: 3 | F20: DASRI | G20: Copilote | H20: Carebone / LLM | I20: faible | J20: Optionnel
A21: ETIQUETTE | B21: Étiquette préparation | C21: 0 | D21: 0.003 | E21: 1 | F21: DAOM | G21: Copilote | H21: Carebone / LLM | I21: faible | J21: Optionnel
A22: AIGUILLE_RECONSTITUTION | B22: Aiguille de reconstitution / prélèvement | C22: 0.04 | D22: 0.01 | E22: 2 | F22: DASRI | G22: Hypothèse interne | H22: Carebone / estimation par masse matière | I22: élevé | J22: Ajoutée pour ACV médicaments nécessitant une reconstitution ; valeur provisoire à revalider par pesée/fournisseur. | Hypothèse interne 0,01 kgCO₂e. Multiplié par nb flacons/j×nb flacon/admin — peut cumuler. À revalider par masse matière ou fournisseur.

Sheet LOCATIONS
A1: Locations journalières
A2: Règle métier : Rythmic et PSE 24 mL HAD sont en location par jour.
A3: methode_id | B3: location_par_jour_eur | C3: ACV | D3: Nbre jour utilisation | E3: kgco2e_location_par_jour | F3: source_cout | G3: source_co2 | H3: commentaire
A4: RYTHMIC_CONT | B4: 12 | C4: 27.431 | D4: 1540 | E4: 0.019812338 | F4: Marchés | G4: à compléter | H4: Location pompe Rythmic par jour.
A5: PSE_24_HAD_CONT | B5: 3.6 | C5: 24.961 | D5: 1250 | E5: 0.0399688 | F5: Marchés | G5: à compléter | H5: Location pousse-seringue HAD par jour ; consommation électrique incluse dans kgCO2e/jour si documentée.

Sheet DM Perfusion de l'hôpital
A1: Data coût à l'utilisation matériel réutilisable intra-hospitalier
A2: Hypothèse de calcul = coût et ACV de fabrication amortis au jour d’utilisation. Les consommables, flacons et reconstitution restent multipliés par le nombre réel d’administrations/jour.
A3: methode_id | B3: Coût à l'achat | C3: ACV | D3: Jours d'utilisation | E3: cout_par_jour | F3: kgco2e_par_jour | G3: source_cout | H3: source_co2 | I3: commentaire | J3: ancienne_methode
A4: PSE_48_CONT | B4: 1250 | C4: 62.34 | D4: 2400 | E4: =B4/D4 -> 0.52083333 | F4: =C4/D4 -> 0.025975 | G4: Hypothèse utilisateur : 1500 € TTC, TVA 20 %, soit 1250 € HT | H4: NA | I4: PSE hospitalier : amortissement au jour d’utilisation, pas de location dans le modèle intra-hospitalier. | J4: Avant : amortissement par administration réelle
A5: POCHE_VOL_CONT | B5: 2160 | C5: 79.683 | D5: 2240 | E5: =B5/D5 -> 0.96428571 | F5: =C5/D5 -> 0.035572768 | G5: NA | H5: NA | I5: Pompe volumétrique classique hospitalière : amortissement au jour d’utilisation pour Poche en pompe volumétrique classique. | J5: Avant : amortissement par administration réelle

Sheet HAD
A1: Paramètres HAD et passages infirmiers
A2: Le logiciel calculera : coût HAD/jour = nombre de passages IDE/jour × 60 €. Impact déplacement = nombre de passages IDE/jour × km_moyen_par_passage × kgco2e_par_km, avec fallback sur kgco2e_passage_ide.
A3: contexte | B3: cout_passage_ide_eur | C3: kgco2e_passage_ide | D3: km_moyen_par_passage | E3: commentaire | F3: kgco2e_par_km
A4: IDEL pour passage | B4: 60 | C4: 4.56 | D4: 30 | E4: Aller-retour IDEL (montagne) : 15 km aller x2 = 30 km/passage. kgco2e_passage_ide = 30 x 0,152 = 4,56 kgCO2e. Corrige le sous-comptage (aller simple 2,28). Facteur 0,152 a revalider vs ADEME Base Carbone (~0,193-0,218 kgCO2e/veh.km). | F4: 0.152

Sheet TEMPS_HUMAIN
A1: Temps humain par méthode
A2: Optionnel. Utile pour comparer le coût hospitalier hors forfait HAD.
A3: methode_id | B3: temps_preparation_min | C3: temps_controle_pharma_min | D3: temps_pose_ide_min | E3: temps_retrait_ide_min | F3: temps_surveillance_min | G3: commentaire
A4: POCHE_VOL_CONT | B4: 10 | C4: 0 | D4: 5 | E4: 5 | F4: 0 | G4: Par poche
A5: PSE_48_CONT | B5: 7 | C5: 0 | D5: 5 | E5: 5 | F5: 0 | G5: Par seringue
A6: RYTHMIC_CONT | B6: 12 | C6: 0 | D6: 5 | E6: 5 | F6: 0 | G6: Par réservoir Rythmic
A7: ANAPA_CONT | B7: 12 | C7: 0 | D7: 5 | E7: 5 | F7: 0 | G7: Par dispositif ANAPA
A8: NEOPUMP_CONT | B8: 20 | C8: 0 | D8: 5 | E8: 5 | F8: 0 | G8: Par dispositif NEOPUMP
A9: POCHE_DISCONT | B9: 10 | C9: 0 | D9: 5 | E9: 5 | F9: 0 | G9: Par administration
A10: PSE_24_HAD_DISCONT | B10: 7 | C10: 0 | D10: 5 | E10: 5 | F10: 0 | G10: En HAD, peut être remplacé par forfait passage IDE

Sheet COUTS_HORAIRES
A1: Coûts horaires
A2: Optionnel. Utilisé seulement si le calcul du temps humain hospitalier est activé.
A3: profil | B3: cout_horaire_eur | C3: source | D3: commentaire
A4: préparateur pharmacie | B4: 15.7 | C4: à compléter | D4: Coût horaire chargé
A5: pharmacien | B5: 25 | C5: à compléter | D5: Coût horaire chargé
A6: IDE hospitalier | B6: 18 | C6: à compléter | D6: Coût horaire chargé

Sheet DECHETS
A1: Facteurs déchets
A2: Optionnel. Calcul déchets = poids item × facteur traitement.
A3: type_dechet | B3: cout_traitement_eur_kg | C3: kgco2e_traitement_kg | D3: source | E3: commentaire
A4: DASRI | B4: 0.75 | C4: 0.943 | D4: Carebone | E4: Incinération/traitement spécifique, inclus emballage primaire, verre ou non
A5: DAOM | B5: 0.18 | C5: 0.386 | D5: Carebone | E5: Déchet assimilé ordures ménagères
A6: CARTON | B6: 0.08 | C6: 0.737 | D6: Carebone | E6: Emballage secondaire ; coût conservateur retenu 0,08 €/kg

Sheet PARAMETRES
A1: Paramètres globaux du modèle
A2: Paramètres généraux modifiables sans toucher au code.
A3: parametre | B3: valeur | C3: unite | D3: commentaire
A4: cout_passage_ide_had | B4: 60 | C4: € / passage | D4: Règle fournie : chaque passage IDEL en HAD coûte 60 €.
A5: inclure_medicament | B5: 1 | C5: 0/1 | D5: 0 = non, 1 = oui.
A6: inclure_reconstitution | B6: 1 | C6: 0/1 | D6: Ajoute les DM de reconstitution pour les présentations nécessitant une reconstitution/poudre.
A7: inclure_temps_humain_hospitalier | B7: 1 | C7: 0/1 | D7: Active le calcul temps humain hospitalier.
A8: inclure_transport_had | B8: 1 | C8: 0/1 | D8: Activé : ajoute les émissions de déplacement IDEL en HAD. Par défaut : 15 km/passage × 0,152 kgCO₂e/km = 2,28 kgCO₂e/passage. Ajuster l'onglet HAD si besoin.
A9: inclure_dechets | B9: 1 | C9: 0/1 | D9: Active coût/CO₂ d’élimination des déchets.
A10: inclure_location | B10: 1 | C10: 0/1 | D10: Rythmic / PSE 24 mL HAD.
A11: inclure_equipement_hospitalier | B11: 1 | C11: 0/1 | D11: Active amortissement pompe volumétrique/PSE 48 mL intra-hospitalier si renseigné.
A12: inclure_items_a_confirmer | B12: 1 | C12: 0/1 | D12: Compte les items marqués 'à confirmer' dans MATERIEL_PAR_METHODE.
A13: duree_traitement_jours_defaut | B13: 1 | C13: jours | D13: Valeur par défaut si non fournie.
A14: item_lingette_reconstitution | B14: COMPRESSE_ANTISEPTIQUE | C14: item_id | D14: Lingette/compresse antiseptique ajoutée si reconstitution nécessaire.
A15: nb_lingette_par_flacon_reconstitution | B15: 1 | C15: unité/flacon | D15: Multiplié par le nombre de flacons/jour nécessitant une reconstitution.
A16: item_solvant_reconstitution | B16: RINCAGE_NACL_10ML | C16: item_id | D16: Proxy solvant de reconstitution 10 mL NaCl/EPPI si poudre.
A17: nb_solvant_10ml_par_flacon_reconstitution | B17: 1 | C17: unité/flacon | D17: Multiplié par le nombre de flacons/jour nécessitant une reconstitution.
A18: item_etiquette_preparation | B18: ETIQUETTE | C18: item_id | D18: Étiquette comptée via MATERIEL_PAR_METHODE par administration.
A19: passage_ide_had_prix_defaut | B19: 60 | C19: € | D19: À garder identique à cout_passage_ide_had sauf changement volontaire.

Sheet README
A1: README — Consignes d'utilisation
A2: Documentation interne de la base de coûts et d'impact carbone.
A3: section | B3: contenu
A4: Objectif | B4: Base de paramètres pour simuler l'impact économique et écologique des méthodes de perfusion proposées par Breaking Stab.
A5: Principe | B5: Les scénarios cliniques ne sont pas saisis dans ce fichier. Ils seront générés automatiquement par le logiciel à partir du moteur inversé.
A6: Règle HAD | B6: Chaque passage infirmier libéral en HAD est valorisé à 60 € par défaut.
A7: Règle location | B7: Rythmic et PSE HAD 24 mL sont modélisés avec une location par jour.
A8: Règle DM | B8: Rythmic = DM captif. Le reste = DM unique, sauf exception renseignée dans les tables.
A9: À compléter | B9: Renseigner les coûts unitaires, kgCO₂e, poids, sources et incertitudes dans FACTEURS_ITEMS, LOCATIONS, HAD, DECHETS et COUTS_HORAIRES.
A10: Amortissement équipement | B10: Les équipements hospitaliers doivent avoir un methode_id identique au code HTML : POCHE_VOL_CONT pour pompe volumétrique classique, PSE_48_CONT pour PSE hospitalier.

Sheet CHANGELOG
A1: CHANGELOG — Suivi des modifications
A2: Tracer chaque modification significative : coût, kgCO₂e, poids, ajout/retrait d'un item ou d'une méthode.
A3: date | B3: auteur | C3: onglet | D3: modification | E3: justification | F3: source
A4: AAAA-MM-JJ | B4: Nom | C4: FACTEURS_ITEMS | D4: À compléter | E4: À compléter | F4: URL ou référence
A5: AAAA-MM-JJ | B5: Nom | C5: LOCATIONS | D5: À compléter | E5: À compléter | F5: URL ou référence
A6: AAAA-MM-JJ | B6: Nom | C6: HAD | D6: À compléter | E6: À compléter | F6: URL ou référence
A7: AAAA-MM-JJ | B7: Nom | C7: DECHETS | D7: À compléter | E7: À compléter | F7: URL ou référence
A8: AAAA-MM-JJ | B8: Nom | C8: PARAMETRES | D8: À compléter | E8: À compléter | F8: URL ou référence
A9: 2026-06-05 | B9: ChatGPT | C9: FACTEURS_ITEMS | D9: Correction poids NeoPump 250/500 à 43 g et ANAPA 250 à 150 g | E9: Validation utilisateur après revue des hypothèses ; poids à revalider par pesée | F9: Fiches techniques fournies + hypothèses utilisateur
A10: 2026-06-05 | B10: ChatGPT | C10: METHODES/MATERIEL/LOCATIONS | D10: Renommage PSE_24_HAD_CONT en PSE_24_HAD_DISCONT | E10: Méthode HAD 24 mL discontinue, ancien identifiant ambigu | F10: Correction utilisateur
A11: 2026-06-05 | B11: ChatGPT | C11: MATERIEL_PAR_METHODE/FACTEURS_ITEMS | D11: Harmonisation item_id Rythmic 100/200 mL | E11: Éviter les non-correspondances lors des jointures | F11: Correction utilisateur
A12: 2026-06-05 | B12: ChatGPT | C12: DM Perfusion de l'hôpital | D12: Correction coût PSE 48 mL à 1250 € HT | E12: 1500 € TTC avec TVA 20 % | F12: Hypothèse utilisateur
A13: 2026-06-05 13:21 | B13: Ajout onglet ACV ATB | C13: Ajout d’un onglet avec ATB Breaking Stab, flacons/dosages, valeurs ACV provisoires calculées selon structure EcovaMED. | D13: ACV ATB | E13: Assistant | F13: FE PA générique à revalider
A14: 2026-06-05 | B14: Ajout reconstitution ACV ATB | C14: Ajout aiguille de reconstitution dans FACTEURS_ITEMS et colonnes X:AH dans ACV ATB. | D14: Toutes lignes ACV ATB | E14: Flacon = reconstitution par défaut ; ampoule/poche/plastique = prêt à diluer/administrer. | F14: À revalider par présentation exacte et pratique locale.
... A19: 2026-06-15 | B19: Claude | C19: PARAMETRES | D19: Documentation du risque transport HAD désactivé par défaut | E19: Transport peut inverser comparaison HAD vs hospitalier selon distances | F19: Analyse interne
A20: 2026-06-15 | B20: v3 | C20: HAD transport | D20: Ajout émissions déplacement IDEL | E20: 15 km/passage × 0,152 kgCO₂e/km = 2,28 kgCO₂e/passage ; transport HAD activé
A21: 2026-06-15 | B21: Correction | C21: ELASTOMERE_GENERIC | D21: Ajout panier matériel diffuseur générique | E21: Le CO₂ DM du diffuseur générique est désormais pris en compte via proxy NEOPUMP 250/500 selon volume. | F21: DP/ChatGPT
A201: 2026-07-03 | B201: Revue assistée | C201: HAD | D201: Transport IDEL en aller-retour : km 15->30 ; kgco2e_passage 2,28->4,56. | E201: L'IDEL revient a sa base ; l'aller simple sous-comptait de moitie le transport HAD. | F201: Commentaire onglet HAD + ADEME.
A202: 2026-07-03 | B202: Revue assistée | C202: FACTEURS_ITEMS + METHODES_PERFUSION | D202: ACV et poids diffuseurs unifies (0,3 kgCO2e / 43 g). | E202: ACV par marque/volume = estimations LLM sans base fournisseur (fausse precision). Base NEOPUMP 500. Couts conserves par marque. | F202: Fiche technique NeoPump 500 mL.

Sheet ACV ATB
A1: ACV ATB — flacons/dosages Breaking Stab (valeurs provisoires calculables)
A3: NOTE | B3: Les valeurs ci-dessous utilisent la structure EcovaMED : masse de PA × FE PA, pertes de fabrication, transport amont PA, conditionnement primaire et emballage secondaire. Le FE PA spécifique n’est pas fourni dans la matrice ; un FE PA générique provisoire est utilisé et doit être remplacé dès qu’un FE PA fournisseur/EcovaMED calculé est disponible. | D3: Paramètre | E3: Valeur | F3: Unité | G3: Source / commentaire
A4: Source ATB | B4: Liste issue de l’outil Breaking Stab / onglet STABILITE et sources CHICAS/Micrel intégrées. | D4: FE_PA_generique_provisoire | E4: 100 | F4: kgCO2e/kg PA | G4: Hypothèse interne provisoire à remplacer par FE PA fournisseur/EcovaMED calculateur
A5: Source coefficients | B5: Matrice EcovaMED v0.7 : pertes PA 5 %, transport excipients/conditionnements 0,095 kgCO2e/kg, flacon verre Europe 7,1 kgCO2e/kg, ampoule verre Europe 5,0 kgCO2e/kg, flacon plastique Europe 4,2 kgCO2e/kg, conditionnement tertiaire carton 1,16 kgCO2e/kg. | D5: Taux_perte_PA | E5: 5 | F5: % | G5: EcovaMED matrice médicament, valeur par défaut
A6: Périmètre | B6: ACV par flacon/unité de médicament avant ajout des DM de perfusion ; destruction/excrétion/administration non incluses ici. | D6: FE_transport_amont_PA | E6: 0.095 | F6: kgCO2e/kg | G6: EcovaMED, transport vers site de fabrication
D7: FE_flacon_verre_Europe | E7: 7.1 | F7: kgCO2e/kg | G7: EcovaMED, conditionnement primaire
D8: FE_ampoule_verre_Europe | E8: 5 | F8: kgCO2e/kg | G8: EcovaMED, conditionnement primaire
D9: FE_flacon_plastique_Europe | E9: 4.2 | F9: kgCO2e/kg | G9: EcovaMED, conditionnement primaire
D10: FE_carton_secondaire | E10: 1.16 | F10: kgCO2e/kg | G10: EcovaMED, conditionnement tertiaire carton
D11: Poids_flacon_verre_defaut | E11: 10 | F11: g | G11: Hypothèse interne à remplacer si poids fournisseur disponible
D12: Poids_ampoule_defaut | E12: 5 | F12: g | G12: Hypothèse interne à remplacer si poids fournisseur disponible
D13: Poids_poche_PEA_defaut | E13: 20 | F13: g | G13: Hypothèse interne pour poches/prêt-à-l’emploi
D14: Poids_carton_proratise_defaut | E14: 3 | F14: g/unité | G14: Hypothèse interne emballage secondaire/tertiaire proratisé
A15: Ajout reconstitution | B15: Les colonnes X:AH classent les présentations en “reconstitution nécessaire” vs “prêt à être dilué/administré” par règle provisoire : flacon = reconstitution ; ampoule/poche/plastique = prêt. Les DM de reconstitution ajoutés par défaut sont 1 seringue 24 mL + 1 aiguille. À revalider par présentation exacte. | D15: DM_reconstitution_defaut | E15: 1 seringue 24 mL + 1 aiguille | F15: par flacon si reconstitution | G15: Hypothèse interne, à ajuster si plusieurs flacons/dose ou pratiques locales
A17: molecule_outil | B17: presentation_flacon_dosage | C17: type_presentation | D17: PA1 | E17: PA1_mg | F17: PA2 | G17: PA2_mg | H17: PA3 | I17: PA3_mg | J17: masse_PA_totale_g | K17: FE_PA_retenu_kgCO2e_kg | L17: ACV_PA_kgCO2e | M17: ACV_transport_PA_kgCO2e | N17: poids_conditionnement_primaire_g | O17: FE_conditionnement_primaire | P17: ACV_conditionnement_primaire_kgCO2e | Q17: poids_carton_proratise_g | R17: ACV_carton_secondaire_kgCO2e | S17: ACV_flacon_total_kgCO2e | T17: niveau_incertitude | U17: source_ATB | V17: source_coefficients | W17: commentaire | X17: statut_preparation | Y17: hypothese_reconstitution | Z17: nb_seringue_reconstitution | AA17: item_seringue_reconstitution | AB17: ACV_seringue_reconstitution_kgCO2e | AC17: nb_aiguille_reconstitution | AD17: item_aiguille_reconstitution | AE17: ACV_aiguille_reconstitution_kgCO2e | AF17: ACV_DM_reconstitution_kgCO2e | AG17: ACV_medicament_total_avec_reconstitution_kgCO2e | AH17: commentaire_preparation
A18: Aciclovir | B18: Flacon 250 mg | C18: flacon verre | D18: Aciclovir | E18: 250 | J18: =IFERROR(SUM(E18,G18,I18)/1000,"") -> 0.25 | K18: =$E$4 -> 100 | L18: =IF(J18="","",J18/1000*K18*(1+$E$5/100)) -> 0.02625 | M18: =IF(J18="","",J18/1000*$E$6) -> 2.375e-05 | N18: =IF(C18="ampoule verre",$E$12,IF(C18="poche PEA",$E$13,$E$11)) -> 10 | O18: =IF(C18="ampoule verre",$E$8,IF(C18="poche PEA",$E$9,$E$7)) -> 7.1 | P18: =N18/1000*O18*(1+$E$5/100) -> 0.07455 | Q18: =$E$14 -> 3 | R18: =Q18/1000*$E$10 -> 0.00348 | S18: =IF(J18="","",SUM(L18:M18,P18,R18)) -> 0.10430375 | T18: =IF(OR(J18="",K18=$E$4),"Élevé - FE PA générique",IF(W18<>"","À vérifier","Moyen")) -> Élevé - FE PA générique | U18: Breaking Stab | V18: EcovaMED v0.7 + hypothèses internes explicites | X18: =IF(A18="","",IF(OR(ISNUMBER(SEARCH("poche",C18)),ISNUMBER(SEARCH("ampoule",C18)),ISNUMBER(SEARCH("plastique",C18))),"Prêt à être dilué / administré (hypothèse)","Reconstitution nécessaire (hypothèse)")) -> Reconstitution nécessaire (hypothèse) | Y18: =IF(A18="","",IF(ISNUMBER(SEARCH("Reconstitution",X18)),"Flacon/poudre : ajout par défaut 1 seringue + 1 aiguille ; à revalider selon présentation exacte.","Ampoule/poche/présentation solution : aucun DM de reconstitution ajouté ; DM de perfusion calculés ailleurs.")) -> Flacon/poudre : ajout par défaut 1 seringue + 1 aiguille ; à revalider selon présentation exacte. | Z18: =IF(A18="","",IF(ISNUMBER(SEARCH("Reconstitution",X18)),1,0)) -> 1 | AA18: =IF(Z18>0,"SERINGUE_PP_24ML","") -> SERINGUE_PP_24ML | AB18: =IF(Z18>0,Z18*VLOOKUP(AA18,FACTEURS_ITEMS!$A$3:$J$30,4,FALSE()),0) -> 0.069 | AC18: =IF(A18="","",IF(ISNUMBER(SEARCH("Reconstitution",X18)),1,0)) -> 1 | AD18: =IF(AC18>0,"AIGUILLE_RECONSTITUTION","") -> AIGUILLE_RECONSTITUTION | AE18: =IF(AC18>0,AC18*VLOOKUP(AD18,FACTEURS_ITEMS!$A$3:$J$30,4,FALSE()),0) -> 0.01 | AF18: =IF(A18="","",AB18+AE18) -> 0.079 | AG18: =IF(A18="","",S18+AF18) -> 0.18330375 | AH18: =IF(A18="","",IF(AF18>0,"ACV médicament incluant PA + conditionnement + DM de reconstitution. Ne comprend pas poche/solvant/tubulure/administration.","ACV médicament sans DM de reconstitution ajouté.")) -> ACV médicament incluant PA + conditionnement + DM de reconstitution. Ne comprend pas poche/solvant/tubulure/administration.
A19: Aciclovir | B19: Flacon 500 mg | C19: flacon verre | D19: Aciclovir | E19: 500 | J19: =IFERROR(SUM(E19,G19,I19)/1000,"") -> 0.5 | K19: =$E$4 -> 100 | L19: =IF(J19="","",J19/1000*K19*(1+$E$5/100)) -> 0.0525 | M19: =IF(J19="","",J19/1000*$E$6) -> 4.75e-05 | N19: =IF(C19="ampoule verre",$E$12,IF(C19="poche PEA",$E$13,$E$11)) -> 10 | O19: =IF(C19="ampoule verre",$E$8,IF(C19="poche PEA",$E$9,$E$7)) -> 7.1 | P19: =N19/1000*O19*(1+$E$5/100) -> 0.07455 | Q19: =$E$14 -> 3 | R19: =Q19/1000*$E$10 -> 0.00348 | S19: =IF(J19="","",SUM(L19:M19,P19,R19)) -> 0.1305775 | T19: =IF(OR(J19="",K19=$E$4),"Élevé - FE PA générique",IF(W19<>"","À vérifier","Moyen")) -> Élevé - FE PA générique | U19: Breaking Stab | V19: EcovaMED v0.7 + hypothèses internes explicites | X19: =IF(A19="","",IF(OR(ISNUMBER(SEARCH("poche",C19)),ISNUMBER(SEARCH("ampoule",C19)),ISNUMBER(SEARCH("plastique",C19))),"Prêt à être dilué / administré (hypothèse)","Reconstitution nécessaire (hypothèse)")) -> Reconstitution nécessaire (hypothèse) | Y19: =IF(A19="","",IF(ISNUMBER(SEARCH("Reconstitution",X19)),"Flacon/poudre : ajout par défaut 1 seringue + 1 aiguille ; à revalider selon présentation exacte.","Ampoule/poche/présentation solution : aucun DM de reconstitution ajouté ; DM de perfusion calculés ailleurs.")) -> Flacon/poudre : ajout par défaut 1 seringue + 1 aiguille ; à revalider selon présentation exacte. | Z19: =IF(A19="","",IF(ISNUMBER(SEARCH("Reconstitution",X19)),1,0)) -> 1 | AA19: =IF(Z19>0,"SERINGUE_PP_24ML","") -> SERINGUE_PP_24ML | AB19: =IF(Z19>0,Z19*VLOOKUP(AA19,FACTEURS_ITEMS!$A$3:$J$30,4,FALSE()),0) -> 0.069 | AC19: =IF(A19="","",IF(ISNUMBER(SEARCH("Reconstitution",X19)),1,0)) -> 1 | AD19: =IF(AC19>0,"AIGUILLE_RECONSTITUTION","") -> AIGUILLE_RECONSTITUTION | AE19: =IF(AC19>0,AC19*VLOOKUP(AD19,FACTEURS_ITEMS!$A$3:$J$30,4,FALSE()),0) -> 0.01 | AF19: =IF(A19="","",AB19+AE19) -> 0.079 | AG19: =IF(A19="","",S19+AF19) -> 0.2095775 | AH19: =IF(A19="","",IF(AF19>0,"ACV médicament incluant PA + conditionnement + DM de reconstitution. Ne comprend pas poche/solvant/tubulure/administration.","ACV médicament sans DM de reconstitution ajouté.")) -> ACV médicament incluant PA + conditionnement + DM de reconstitution. Ne comprend pas poche/solvant/tubulure/administration.
A20: Amikacine | B20: Flacon/ampoule 250 mg | C20: ampoule verre | D20: Amikacine | E20: 250 | J20: =IFERROR(SUM(E20,G20,I20)/1000,"") -> 0.25 | K20: =$E$4 -> 100 | L20: =IF(J20="","",J20/1000*K20*(1+$E$5/100)) -> 0.02625 | M20: =IF(J20="","",J20/1000*$E$6) -> 2.375e-05 | N20: =IF(C20="ampoule verre",$E$12,IF(C20="poche PEA",$E$13,$E$11)) -> 5 | O20: =IF(C20="ampoule verre",$E$8,IF(C20="poche PEA",$E$9,$E$7)) -> 5 | P20: =N20/1000*O20*(1+$E$5/100) -> 0.02625 | Q20: =$E$14 -> 3 | R20: =Q20/1000*$E$10 -> 0.00348 | S20: =IF(J20="","",SUM(L20:M20,P20,R20)) -> 0.05600375 | T20: =IF(OR(J20="",K20=$E$4),"Élevé - FE PA générique",IF(W20<>"","À vérifier","Moyen")) -> Élevé - FE PA générique | U20: Breaking Stab | V20: EcovaMED v0.7 + hypothèses internes explicites | X20: =IF(A20="","",IF(OR(ISNUMBER(SEARCH("poche",C20)),ISNUMBER(SEARCH("ampoule",C20)),ISNUMBER(SEARCH("plastique",C20))),"Prêt à être dilué / administré (hypothèse)","Reconstitution nécessaire (hypothèse)")) -> Prêt à être dilué / administré (hypothèse) | Y20: =IF(A20="","",IF(ISNUMBER(SEARCH("Reconstitution",X20)),"Flacon/poudre : ajout par défaut 1 seringue + 1 aiguille ; à revalider selon présentation exacte.","Ampoule/poche/présentation solution : aucun DM de reconstitution ajouté ; DM de perfusion calculés ailleurs.")) -> Ampoule/poche/présentation solution : aucun DM de reconstitution ajouté ; DM de perfusion calculés ailleurs. | Z20: =IF(A20="","",IF(ISNUMBER(SEARCH("Reconstitution",X20)),1,0)) -> 0 | AA20: =IF(Z20>0,"SERINGUE_PP_24ML","") | AB20: =IF(Z20>0,Z20*VLOOKUP(AA20,FACTEURS_ITEMS!$A$3:$J$30,4,FALSE()),0) -> 0 | AC20: =IF(A20="","",IF(ISNUMBER(SEARCH("Reconstitution",X20)),1,0)) -> 0 | AD20: =IF(AC20>0,"AIGUILLE_RECONSTITUTION","") | AE20: =IF(AC20>0,AC20*VLOOKUP(AD20,FACTEURS_ITEMS!$A$3:$J$30,4,FALSE()),0) -> 0 | AF20: =IF(A20="","",AB20+AE20) -> 0 | AG20: =IF(A20="","",S20+AF20) -> 0.05600375 | AH20: =IF(A20="","",IF(AF20>0,"ACV médicament incluant PA + conditionnement + DM de reconstitution. Ne comprend pas poche/solvant/tubulure/administration.","ACV médicament sans DM de reconstitution ajouté.")) -> ACV médicament sans DM de reconstitution ajouté.
A21: Amikacine | B21: Flacon/ampoule 500 mg | C21: ampoule verre | D21: Amikacine | E21: 500 | J21: =IFERROR(SUM(E21,G21,I21)/1000,"") -> 0.5 | K21: =$E$4 -> 100 | L21: =IF(J21="","",J21/1000*K21*(1+$E$5/100)) -> 0.0525 | M21: =IF(J21="","",J21/1000*$E$6) -> 4.75e-05 | N21: =IF(C21="ampoule verre",$E$12,IF(C21="poche PEA",$E$13,$E$11)) -> 5 | O21: =IF(C21="ampoule verre",$E$8,IF(C21="poche PEA",$E$9,$E$7)) -> 5 | P21: =N21/1000*O21*(1+$E$5/100) -> 0.02625 | Q21: =$E$14 -> 3 | R21: =Q21/1000*$E$10 -> 0.00348 | S21: =IF(J21="","",SUM(L21:M21,P21,R21)) -> 0.0822775 | T21: =IF(OR(J21="",K21=$E$4),"Élevé - FE PA générique",IF(W21<>"","À vérifier","Moyen")) -> Élevé - FE PA générique | U21: Breaking Stab | V21: EcovaMED v0.7 + hypothèses internes explicites | X21: =IF(A21="","",IF(OR(ISNUMBER(SEARCH("poche",C21)),ISNUMBER(SEARCH("ampoule",C21)),ISNUMBER(SEARCH("plastique",C21))),"Prêt à être dilué / administré (hypothèse)","Reconstitution nécessaire (hypothèse)")) -> Prêt à être dilué / administré (hypothèse) | Y21: =IF(A21="","",IF(ISNUMBER(SEARCH("Reconstitution",X21)),"Flacon/poudre : ajout par défaut 1 seringue + 1 aiguille ; à revalider selon présentation exacte.","Ampoule/poche/présentation solution : aucun DM de reconstitution ajouté ; DM de perfusion calculés ailleurs.")) -> Ampoule/poche/présentation solution : aucun DM de reconstitution ajouté ; DM de perfusion calculés ailleurs. | Z21: =IF(A21="","",IF(ISNUMBER(SEARCH("Reconstitution",X21)),1,0)) -> 0 | AA21: =IF(Z21>0,"SERINGUE_PP_24ML","") | AB21: =IF(Z21>0,Z21*VLOOKUP(AA21,FACTEURS_ITEMS!$A$3:$J$30,4,FALSE()),0) -> 0 | AC21: =IF(A21="","",IF(ISNUMBER(SEARCH("Reconstitution",X21)),1,0)) -> 0 | AD21: =IF(AC21>0,"AIGUILLE_RECONSTITUTION","") | AE21: =IF(AC21>0,AC21*VLOOKUP(AD21,FACTEURS_ITEMS!$A$3:$J$30,4,FALSE()),0) -> 0 | AF21: =IF(A21="","",AB21+AE21) -> 0 | AG21: =IF(A21="","",S21+AF21) -> 0.0822775 | AH21: =IF(A21="","",IF(AF21>0,"ACV médicament incluant PA + conditionnement + DM de reconstitution. Ne comprend pas poche/solvant/tubulure/administration.","ACV médicament sans DM de reconstitution ajouté.")) -> ACV médicament sans DM de reconstitution ajouté.
A22: Amikacine | B22: Flacon/ampoule 1 g | C22: flacon verre | D22: Amikacine | E22: 1000 | J22: =IFERROR(SUM(E22,G22,I22)/1000,"") -> 1 | K22: =$E$4 -> 100 | L22: =IF(J22="","",J22/1000*K22*(1+$E$5/100)) -> 0.105 | M22: =IF(J22="","",J22/1000*$E$6) -> 9.5e-05 | N22: =IF(C22="ampoule verre",$E$12,IF(C22="poche PEA",$E$13,$E$11)) -> 10 | O22: =IF(C22="ampoule verre",$E$8,IF(C22="poche PEA",$E$9,$E$7)) -> 7.1 | P22: =N22/1000*O22*(1+$E$5/100) -> 0.07455 | Q22: =$E$14 -> 3 | R22: =Q22/1000*$E$10 -> 0.00348 | S22: =IF(J22="","",SUM(L22:M22,P22,R22)) -> 0.183125 | T22: =IF(OR(J22="",K22=$E$4),"Élevé - FE PA générique",IF(W22<>"","À vérifier","Moyen")) -> Élevé - FE PA générique | U22: Breaking Stab | V22: EcovaMED v0.7 + hypothèses internes explicites | X22: =IF(A22="","",IF(OR(ISNUMBER(SEARCH("poche",C22)),ISNUMBER(SEARCH("ampoule",C22)),ISNUMBER(SEARCH("plastique",C22))),"Prêt à être dilué / administré (hypothèse)","Reconstitution nécessaire (hypothèse)")) -> Reconstitution nécessaire (hypothèse) | Y22: =IF(A22="","",IF(ISNUMBER(SEARCH("Reconstitution",X22)),"Flacon/poudre : ajout par défaut 1 seringue + 1 aiguille ; à revalider selon présentation exacte.","Ampoule/poche/présentation solution : aucun DM de reconstitution ajouté ; DM de perfusion calculés ailleurs.")) -> Flacon/poudre : ajout par défaut 1 seringue + 1 aiguille ; à revalider selon présentation exacte. | Z22: =IF(A22="","",IF(ISNUMBER(SEARCH("Reconstitution",X22)),1,0)) -> 1 | AA22: =IF(Z22>0,"SERINGUE_PP_24ML","") -> SERINGUE_PP_24ML | AB22: =IF(Z22>0,Z22*VLOOKUP(AA22,FACTEURS_ITEMS!$A$3:$J$30,4,FALSE()),0) -> 0.069 | AC22: =IF(A22="","",IF(ISNUMBER(SEARCH("Reconstitution",X22)),1,0)) -> 1 | AD22: =IF(AC22>0,"AIGUILLE_RECONSTITUTION","") -> AIGUILLE_RECONSTITUTION | AE22: =IF(AC22>0,AC22*VLOOKUP(AD22,FACTEURS_ITEMS!$A$3:$J$30,4,FALSE()),0) -> 0.01 | AF22: =IF(A22="","",AB22+AE22) -> 0.079 | AG22: =IF(A22="","",S22+AF22) -> 0.262125 | AH22: =IF(A22="","",IF(AF22>0,"ACV médicament incluant PA + conditionnement + DM de reconstitution. Ne comprend pas poche/solvant/tubulure/administration.","ACV médicament sans DM de reconstitution ajouté.")) -> ACV médicament incluant PA + conditionnement + DM de reconstitution. Ne comprend pas poche/solvant/tubulure/administration.
A23: Amoxicilline | B23: Flacon 1 g | C23: flacon verre | D23: Amoxicilline | E23: 1000 | J23: =IFERROR(SUM(E23,G23,I23)/1000,"") -> 1 | K23: =$E$4 -> 100 | L23: =IF(J23="","",J23/1000*K23*(1+$E$5/100)) -> 0.105 | M23: =IF(J23="","",J23/1000*$E$6) -> 9.5e-05 | N23: =IF(C23="ampoule verre",$E$12,IF(C23="poche PEA",$E$13,$E$11)) -> 10 | O23: =IF(C23="ampoule verre",$E$8,IF(C23="poche PEA",$E$9,$E$7)) -> 7.1 | P23: =N23/1000*O23*(1+$E$5/100) -> 0.07455 | Q23: =$E$14 -> 3 | R23: =Q23/1000*$E$10 -> 0.00348 | S23: =IF(J23="","",SUM(L23:M23,P23,R23)) -> 0.183125 | T23: =IF(OR(J23="",K23=$E$4),"Élevé - FE PA générique",IF(W23<>"","À vérifier","Moyen")) -> Élevé - FE PA générique | U23: Breaking Stab | V23: EcovaMED v0.7 + hypothèses internes explicites | X23: =IF(A23="","",IF(OR(ISNUMBER(SEARCH("poche",C23)),ISNUMBER(SEARCH("ampoule",C23)),ISNUMBER(SEARCH("plastique",C23))),"Prêt à être dilué / administré (hypothèse)","Reconstitution nécessaire (hypothèse)")) -> Reconstitution nécessaire (hypothèse) | Y23: =IF(A23="","",IF(ISNUMBER(SEARCH("Reconstitution",X23)),"Flacon/poudre : ajout par défaut 1 seringue + 1 aiguille ; à revalider selon présentation exacte.","Ampoule/poche/présentation solution : aucun DM de reconstitution ajouté ; DM de perfusion calculés ailleurs.")) -> Flacon/poudre : ajout par défaut 1 seringue + 1 aiguille ; à revalider selon présentation exacte. | Z23: =IF(A23="","",IF(ISNUMBER(SEARCH("Reconstitution",X23)),1,0)) -> 1 | AA23: =IF(Z23>0,"SERINGUE_PP_24ML","") -> SERINGUE_PP_24ML | AB23: =IF(Z23>0,Z23*VLOOKUP(AA23,FACTEURS_ITEMS!$A$3:$J$30,4,FALSE()),0) -> 0.069 | AC23: =IF(A23="","",IF(ISNUMBER(SEARCH("Reconstitution",X23)),1,0)) -> 1 | AD23: =IF(AC23>0,"AIGUILLE_RECONSTITUTION","") -> AIGUILLE_RECONSTITUTION | AE23: =IF(AC23>0,AC23*VLOOKUP(AD23,FACTEURS_ITEMS!$A$3:$J$30,4,FALSE()),0) -> 0.01 | AF23: =IF(A23="","",AB23+AE23) -> 0.079 | AG23: =IF(A23="","",S23+AF23) -> 0.262125 | AH23: =IF(A23="","",IF(AF23>0,"ACV médicament incluant PA + conditionnement + DM de reconstitution. Ne comprend pas poche/solvant/tubulure/administration.","ACV médicament sans DM de reconstitution ajouté.")) -> ACV médicament incluant PA + conditionnement + DM de reconstitution. Ne comprend pas poche/solvant/tubulure/administration.
A24: Amoxicilline | B24: Flacon 2 g | C24: flacon verre | D24: Amoxicilline | E24: 2000 | J24: =IFERROR(SUM(E24,G24,I24)/1000,"") -> 2 | K24: =$E$4 -> 100 | L24: =IF(J24="","",J24/1000*K24*(1+$E$5/100)) -> 0.21 | M24: =IF(J24="","",J24/1000*$E$6) -> 0.00019 | N24: =IF(C24="ampoule verre",$E$12,IF(C24="poche PEA",$E$13,$E$11)) -> 10 | O24: =IF(C24="ampoule verre",$E$8,IF(C24="poche PEA",$E$9,$E$7)) -> 7.1 | P24: =N24/1000*O24*(1+$E$5/100) -> 0.07455 | Q24: =$E$14 -> 3 | R24: =Q24/1000*$E$10 -> 0.00348 | S24: =IF(J24="","",SUM(L24:M24,P24,R24)) -> 0.28822 | T24: =IF(OR(J24="",K24=$E$4),"Élevé - FE PA générique",IF(W24<>"","À vérifier","Moyen")) -> Élevé - FE PA générique | U24: Breaking Stab | V24: EcovaMED v0.7 + hypothèses internes explicites | X24: =IF(A24="","",IF(OR(ISNUMBER(SEARCH("poche",C24)),ISNUMBER(SEARCH("ampoule",C24)),ISNUMBER(SEARCH("plastique",C24))),"Prêt à être dilué / administré (hypothèse)","Reconstitution nécessaire (hypothèse)")) -> Reconstitution nécessaire (hypothèse) | Y24: =IF(A24="","",IF(ISNUMBER(SEARCH("Reconstitution",X24)),"Flacon/poudre : ajout par défaut 1 seringue + 1 aiguille ; à revalider selon présentation exacte.","Ampoule/poche/présentation solution : aucun DM de reconstitution ajouté ; DM de perfusion calculés ailleurs.")) -> Flacon/poudre : ajout par défaut 1 seringue + 1 aiguille ; à revalider selon présentation exacte. | Z24: =IF(A24="","",IF(ISNUMBER(SEARCH("Reconstitution",X24)),1,0)) -> 1 | AA24: =IF(Z24>0,"SERINGUE_PP_24ML","") -> SERINGUE_PP_24ML | AB24: =IF(Z24>0,Z24*VLOOKUP(AA24,FACTEURS_ITEMS!$A$3:$J$30,4,FALSE()),0) -> 0.069 | AC24: =IF(A24="","",IF(ISNUMBER(SEARCH("Reconstitution",X24)),1,0)) -> 1 | AD24: =IF(AC24>0,"AIGUILLE_RECONSTITUTION","") -> AIGUILLE_RECONSTITUTION | AE24: =IF(AC24>0,AC24*VLOOKUP(AD24,FACTEURS_ITEMS!$A$3:$J$30,4,FALSE()),0) -> 0.01 | AF24: =IF(A24="","",AB24+AE24) -> 0.079 | AG24: =IF(A24="","",S24+AF24) -> 0.36722 | AH24: =IF(A24="","",IF(AF24>0,"ACV médicament incluant PA + conditionnement + DM de reconstitution. Ne comprend pas poche/solvant/tubulure/administration.","ACV médicament sans DM de reconstitution ajouté.")) -> ACV médicament incluant PA + conditionnement + DM de reconstitution. Ne comprend pas poche/solvant/tubulure/administration.
A25: Amoxicilline/acide clavulanique | B25: Flacon 1 g/200 mg | C25: flacon verre | D25: Amoxicilline | E25: 1000 | F25: Acide clavulanique | G25: 200 | J25: =IFERROR(SUM(E25,G25,I25)/1000,"") -> 1.2 | K25: =$E$4 -> 100 | L25: =IF(J25="","",J25/1000*K25*(1+$E$5/100)) -> 0.126 | M25: =IF(J25="","",J25/1000*$E$6) -> 0.000114 | N25: =IF(C25="ampoule verre",$E$12,IF(C25="poche PEA",$E$13,$E$11)) -> 10 | O25: =IF(C25="ampoule verre",$E$8,IF(C25="poche PEA",$E$9,$E$7)) -> 7.1 | P25: =N25/1000*O25*(1+$E$5/100) -> 0.07455 | Q25: =$E$14 -> 3 | R25: =Q25/1000*$E$10 -> 0.00348 | S25: =IF(J25="","",SUM(L25:M25,P25,R25)) -> 0.204144 | T25: =IF(OR(J25="",K25=$E$4),"Élevé - FE PA générique",IF(W25<>"","À vérifier","Moyen")) -> Élevé - FE PA générique | U25: Breaking Stab | V25: EcovaMED v0.7 + hypothèses internes explicites | X25: =IF(A25="","",IF(OR(ISNUMBER(SEARCH("poche",C25)),ISNUMBER(SEARCH("ampoule",C25)),ISNUMBER(SEARCH("plastique",C25))),"Prêt à être dilué / administré (hypothèse)","Reconstitution nécessaire (hypothèse)")) -> Reconstitution nécessaire (hypothèse) | Y25: =IF(A25="","",IF(ISNUMBER(SEARCH("Reconstitution",X25)),"Flacon/poudre : ajout par défaut 1 seringue + 1 aiguille ; à revalider selon présentation exacte.","Ampoule/poche/présentation solution : aucun DM de reconstitution ajouté ; DM de perfusion calculés ailleurs.")) -> Flacon/poudre : ajout par défaut 1 seringue + 1 aiguille ; à revalider selon présentation exacte. | Z25: =IF(A25="","",IF(ISNUMBER(SEARCH("Reconstitution",X25)),1,0)) -> 1 | AA25: =IF(Z25>0,"SERINGUE_PP_24ML","") -> SERINGUE_PP_24ML | AB25: =IF(Z25>0,Z25*VLOOKUP(AA25,FACTEURS_ITEMS!$A$3:$J$30,4,FALSE()),0) -> 0.069 | AC25: =IF(A25="","",IF(ISNUMBER(SEARCH("Reconstitution",X25)),1,0)) -> 1 | AD25: =IF(AC25>0,"AIGUILLE_RECONSTITUTION","") -> AIGUILLE_RECONSTITUTION | AE25: =IF(AC25>0,AC25*VLOOKUP(AD25,FACTEURS_ITEMS!$A$3:$J$30,4,FALSE()),0) -> 0.01 | AF25: =IF(A25="","",AB25+AE25) -> 0.079 | AG25: =IF(A25="","",S25+AF25) -> 0.283144 | AH25: =IF(A25="","",IF(AF25>0,"ACV médicament incluant PA + conditionnement + DM de reconstitution. Ne comprend pas poche/solvant/tubulure/administration.","ACV médicament sans DM de reconstitution ajouté.")) -> ACV médicament incluant PA + conditionnement + DM de reconstitution. Ne comprend pas poche/solvant/tubulure/administration.
A26: Amoxicilline/acide clavulanique | B26: Flacon 2 g/200 mg | C26: flacon verre | D26: Amoxicilline | E26: 2000 | F26: Acide clavulanique | G26: 200 | J26: =IFERROR(SUM(E26,G26,I26)/1000,"") -> 2.2 | K26: =$E$4 -> 100 | L26: =IF(J26="","",J26/1000*K26*(1+$E$5/100)) -> 0.231 | M26: =IF(J26="","",J26/1000*$E$6) -> 0.000209 | N26: =IF(C26="ampoule verre",$E$12,IF(C26="poche PEA",$E$13,$E$11)) -> 10 | O26: =IF(C26="ampoule verre",$E$8,IF(C26="poche PEA",$E$9,$E$7)) -> 7.1 | P26: =N26/1000*O26*(1+$E$5/100) -> 0.07455 | Q26: =$E$14 -> 3 | R26: =Q26/1000*$E$10 -> 0.00348 | S26: =IF(J26="","",SUM(L26:M26,P26,R26)) -> 0.309239 | T26: =IF(OR(J26="",K26=$E$4),"Élevé - FE PA générique",IF(W26<>"","À vérifier","Moyen")) -> Élevé - FE PA générique | U26: Breaking Stab | V26: EcovaMED v0.7 + hypothèses internes explicites | X26: =IF(A26="","",IF(OR(ISNUMBER(SEARCH("poche",C26)),ISNUMBER(SEARCH("ampoule",C26)),ISNUMBER(SEARCH("plastique",C26))),"Prêt à être dilué / administré (hypothèse)","Reconstitution nécessaire (hypothèse)")) -> Reconstitution nécessaire (hypothèse) | Y26: =IF(A26="","",IF(ISNUMBER(SEARCH("Reconstitution",X26)),"Flacon/poudre : ajout par défaut 1 seringue + 1 aiguille ; à revalider selon présentation exacte.","Ampoule/poche/présentation solution : aucun DM de reconstitution ajouté ; DM de perfusion calculés ailleurs.")) -> Flacon/poudre : ajout par défaut 1 seringue + 1 aiguille ; à revalider selon présentation exacte. | Z26: =IF(A26="","",IF(ISNUMBER(SEARCH("Reconstitution",X26)),1,0)) -> 1 | AA26: =IF(Z26>0,"SERINGUE_PP_24ML","") -> SERINGUE_PP_24ML | AB26: =IF(Z26>0,Z26*VLOOKUP(AA26,FACTEURS_ITEMS!$A$3:$J$30,4,FALSE()),0) -> 0.069 | AC26: =IF(A26="","",IF(ISNUMBER(SEARCH("Reconstitution",X26)),1,0)) -> 1 | AD26: =IF(AC26>0,"AIGUILLE_RECONSTITUTION","") -> AIGUILLE_RECONSTITUTION | AE26: =IF(AC26>0,AC26*VLOOKUP(AD26,FACTEURS_ITEMS!$A$3:$J$30,4,FALSE()),0) -> 0.01 | AF26: =IF(A26="","",AB26+AE26) -> 0.079 | AG26: =IF(A26="","",S26+AF26) -> 0.388239 | AH26: =IF(A26="","",IF(AF26>0,"ACV médicament incluant PA + conditionnement + DM de reconstitution. Ne comprend pas poche/solvant/tubulure/administration.","ACV médicament sans DM de reconstitution ajouté.")) -> ACV médicament incluant PA + conditionnement + DM de reconstitution. Ne comprend pas poche/solvant/tubulure/administration.
A27: Ampicilline | B27: Flacon 1 g | C27: flacon verre | D27: Ampicilline | E27: 1000 | J27: =IFERROR(SUM(E27,G27,I27)/1000,"") -> 1 | K27: =$E$4 -> 100 | L27: =IF(J27="","",J27/1000*K27*(1+$E$5/100)) -> 0.105 | M27: =IF(J27="","",J27/1000*$E$6) -> 9.5e-05 | N27: =IF(C27="ampoule verre",$E$12,IF(C27="poche PEA",$E$13,$E$11)) -> 10 | O27: =IF(C27="ampoule verre",$E$8,IF(C27="poche PEA",$E$9,$E$7)) -> 7.1 | P27: =N27/1000*O27*(1+$E$5/100) -> 0.07455 | Q27: =$E$14 -> 3 | R27: =Q27/1000*$E$10 -> 0.00348 | S27: =IF(J27="","",SUM(L27:M27,P27,R27)) -> 0.183125 | T27: =IF(OR(J27="",K27=$E$4),"Élevé - FE PA générique",IF(W27<>"","À vérifier","Moyen")) -> Élevé - FE PA générique | U27: CHICAS/Breaking Stab | V27: EcovaMED v0.7 + hypothèses internes explicites | X27: =IF(A27="","",IF(OR(ISNUMBER(SEARCH("poche",C27)),ISNUMBER(SEARCH("ampoule",C27)),ISNUMBER(SEARCH("plastique",C27))),"Prêt à être dilué / administré (hypothèse)","Reconstitution nécessaire (hypothèse)")) -> Reconstitution nécessaire (hypothèse) | Y27: =IF(A27="","",IF(ISNUMBER(SEARCH("Reconstitution",X27)),"Flacon/poudre : ajout par défaut 1 seringue + 1 aiguille ; à revalider selon présentation exacte.","Ampoule/poche/présentation solution : aucun DM de reconstitution ajouté ; DM de perfusion calculés ailleurs.")) -> Flacon/poudre : ajout par défaut 1 seringue + 1 aiguille ; à revalider selon présentation exacte. | Z27: =IF(A27="","",IF(ISNUMBER(SEARCH("Reconstitution",X27)),1,0)) -> 1 | AA27: =IF(Z27>0,"SERINGUE_PP_24ML","") -> SERINGUE_PP_24ML | AB27: =IF(Z27>0,Z27*VLOOKUP(AA27,FACTEURS_ITEMS!$A$3:$J$30,4,FALSE()),0) -> 0.069 | AC27: =IF(A27="","",IF(ISNUMBER(SEARCH("Reconstitution",X27)),1,0)) -> 1 | AD27: =IF(AC27>0,"AIGUILLE_RECONSTITUTION","") -> AIGUILLE_RECONSTITUTION | AE27: =IF(AC27>0,AC27*VLOOKUP(AD27,FACTEURS_ITEMS!$A$3:$J$30,4,FALSE()),0) -> 0.01 | AF27: =IF(A27="","",AB27+AE27) -> 0.079 | AG27: =IF(A27="","",S27+AF27) -> 0.262125 | AH27: =IF(A27="","",IF(AF27>0,"ACV médicament incluant PA + conditionnement + DM de reconstitution. Ne comprend pas poche/solvant/tubulure/administration.","ACV médicament sans DM de reconstitution ajouté.")) -> ACV médicament incluant PA + conditionnement + DM de reconstitution. Ne comprend pas poche/solvant/tubulure/administration.
A28: Ampicilline | B28: Flacon 2 g | C28: flacon verre | D28: Ampicilline | E28: 2000 | J28: =IFERROR(SUM(E28,G28,I28)/1000,"") -> 2 | K28: =$E$4 -> 100 | L28: =IF(J28="","",J28/1000*K28*(1+$E$5/100)) -> 0.21 | M28: =IF(J28="","",J28/1000*$E$6) -> 0.00019 | N28: =IF(C28="ampoule verre",$E$12,IF(C28="poche PEA",$E$13,$E$11)) -> 10 | O28: =IF(C28="ampoule verre",$E$8,IF(C28="poche PEA",$E$9,$E$7)) -> 7.1 | P28: =N28/1000*O28*(1+$E$5/100) -> 0.07455 | Q28: =$E$14 -> 3 | R28: =Q28/1000*$E$10 -> 0.00348 | S28: =IF(J28="","",SUM(L28:M28,P28,R28)) -> 0.28822 | T28: =IF(OR(J28="",K28=$E$4),"Élevé - FE PA générique",IF(W28<>"","À vérifier","Moyen")) -> Élevé - FE PA générique | U28: CHICAS/Breaking Stab | V28: EcovaMED v0.7 + hypothèses internes explicites | X28: =IF(A28="","",IF(OR(ISNUMBER(SEARCH("poche",C28)),ISNUMBER(SEARCH("ampoule",C28)),ISNUMBER(SEARCH("plastique",C28))),"Prêt à être dilué / administré (hypothèse)","Reconstitution nécessaire (hypothèse)")) -> Reconstitution nécessaire (hypothèse) | Y28: =IF(A28="","",IF(ISNUMBER(SEARCH("Reconstitution",X28)),"Flacon/poudre : ajout par défaut 1 seringue + 1 aiguille ; à revalider selon présentation exacte.","Ampoule/poche/présentation solution : aucun DM de reconstitution ajouté ; DM de perfusion calculés ailleurs.")) -> Flacon/poudre : ajout par défaut 1 seringue + 1 aiguille ; à revalider selon présentation exacte. | Z28: =IF(A28="","",IF(ISNUMBER(SEARCH("Reconstitution",X28)),1,0)) -> 1 | AA28: =IF(Z28>0,"SERINGUE_PP_24ML","") -> SERINGUE_PP_24ML | AB28: =IF(Z28>0,Z28*VLOOKUP(AA28,FACTEURS_ITEMS!$A$3:$J$30,4,FALSE()),0) -> 0.069 | AC28: =IF(A28="","",IF(ISNUMBER(SEARCH("Reconstitution",X28)),1,0)) -> 1 | AD28: =IF(AC28>0,"AIGUILLE_RECONSTITUTION","") -> AIGUILLE_RECONSTITUTION | AE28: =IF(AC28>0,AC28*VLOOKUP(AD28,FACTEURS_ITEMS!$A$3:$J$30,4,FALSE()),0) -> 0.01 | AF28: =IF(A28="","",AB28+AE28) -> 0.079 | AG28: =IF(A28="","",S28+AF28) -> 0.36722 | AH28: =IF(A28="","",IF(AF28>0,"ACV médicament incluant PA + conditionnement + DM de reconstitution. Ne comprend pas poche/solvant/tubulure/administration.","ACV médicament sans DM de reconstitution ajouté.")) -> ACV médicament incluant PA + conditionnement + DM de reconstitution. Ne comprend pas poche/solvant/tubulure/administration.
A29: Artesunate | B29: Flacon 60 mg | C29: flacon verre | D29: Artésunate | E29: 60 | J29: =IFERROR(SUM(E29,G29,I29)/1000,"") -> 0.06 | K29: =$E$4 -> 100 | L29: =IF(J29="","",J29/1000*K29*(1+$E$5/100)) -> 0.0063 | M29: =IF(J29="","",J29/1000*$E$6) -> 5.7e-06 | N29: =IF(C29="ampoule verre",$E$12,IF(C29="poche PEA",$E$13,$E$11)) -> 10 | O29: =IF(C29="ampoule verre",$E$8,IF(C29="poche PEA",$E$9,$E$7)) -> 7.1 | P29: =N29/1000*O29*(1+$E$5/100) -> 0.07455 | Q29: =$E$14 -> 3 | R29: =Q29/1000*$E$10 -> 0.00348 | S29: =IF(J29="","",SUM(L29:M29,P29,R29)) -> 0.0843357 | T29: =IF(OR(J29="",K29=$E$4),"Élevé - FE PA générique",IF(W29<>"","À vérifier","Moyen")) -> Élevé - FE PA générique | U29: Breaking Stab | V29: EcovaMED v0.7 + hypothèses internes explicites | X29: =IF(A29="","",IF(OR(ISNUMBER(SEARCH("poche",C29)),ISNUMBER(SEARCH("ampoule",C29)),ISNUMBER(SEARCH("plastique",C29))),"Prêt à être dilué / administré (hypothèse)","Reconstitution nécessaire (hypothèse)")) -> Reconstitution nécessaire (hypothèse) | Y29: =IF(A29="","",IF(ISNUMBER(SEARCH("Reconstitution",X29)),"Flacon/poudre : ajout par défaut 1 seringue + 1 aiguille ; à revalider selon présentation exacte.","Ampoule/poche/présentation solution : aucun DM de reconstitution ajouté ; DM de perfusion calculés ailleurs.")) -> Flacon/poudre : ajout par défaut 1 seringue + 1 aiguille ; à revalider selon présentation exacte. | Z29: =IF(A29="","",IF(ISNUMBER(SEARCH("Reconstitution",X29)),1,0)) -> 1 | AA29: =IF(Z29>0,"SERINGUE_PP_24ML","") -> SERINGUE_PP_24ML | AB29: =IF(Z29>0,Z29*VLOOKUP(AA29,FACTEURS_ITEMS!$A$3:$J$30,4,FALSE()),0) -> 0.069 | AC29: =IF(A29="","",IF(ISNUMBER(SEARCH("Reconstitution",X29)),1,0)) -> 1 | AD29: =IF(AC29>0,"AIGUILLE_RECONSTITUTION","") -> AIGUILLE_RECONSTITUTION | AE29: =IF(AC29>0,AC29*VLOOKUP(AD29,FACTEURS_ITEMS!$A$3:$J$30,4,FALSE()),0) -> 0.01 | AF29: =IF(A29="","",AB29+AE29) -> 0.079 | AG29: =IF(A29="","",S29+AF29) -> 0.1633357 | AH29: =IF(A29="","",IF(AF29>0,"ACV médicament incluant PA + conditionnement + DM de reconstitution. Ne comprend pas poche/solvant/tubulure/administration.","ACV médicament sans DM de reconstitution ajouté.")) -> ACV médicament incluant PA + conditionnement + DM de reconstitution. Ne comprend pas poche/solvant/tubulure/administration.
A30: Aztréonam | B30: Flacon 1 g | C30: flacon verre | D30: Aztréonam | E30: 1000 | J30: =IFERROR(SUM(E30,G30,I30)/1000,"") -> 1 | K30: =$E$4 -> 100 | L30: =IF(J30="","",J30/1000*K30*(1+$E$5/100)) -> 0.105 | M30: =IF(J30="","",J30/1000*$E$6) -> 9.5e-05 | N30: =IF(C30="ampoule verre",$E$12,IF(C30="poche PEA",$E$13,$E$11)) -> 10 | O30: =IF(C30="ampoule verre",$E$8,IF(C30="poche PEA",$E$9,$E$7)) -> 7.1 | P30: =N30/1000*O30*(1+$E$5/100) -> 0.07455 | Q30: =$E$14 -> 3 | R30: =Q30/1000*$E$10 -> 0.00348 | S30: =IF(J30="","",SUM(L30:M30,P30,R30)) -> 0.183125 | T30: =IF(OR(J30="",K30=$E$4),"Élevé - FE PA générique",IF(W30<>"","À vérifier","Moyen")) -> Élevé - FE PA générique | U30: Breaking Stab | V30: EcovaMED v0.7 + hypothèses internes explicites | X30: =IF(A30="","",IF(OR(ISNUMBER(SEARCH("poche",C30)),ISNUMBER(SEARCH("ampoule",C30)),ISNUMBER(SEARCH("plastique",C30))),"Prêt à être dilué / administré (hypothèse)","Reconstitution nécessaire (hypothèse)")) -> Reconstitution nécessaire (hypothèse) | Y30: =IF(A30="","",IF(ISNUMBER(SEARCH("Reconstitution",X30)),"Flacon/poudre : ajout par défaut 1 seringue + 1 aiguille ; à revalider selon présentation exacte.","Ampoule/poche/présentation solution : aucun DM de reconstitution ajouté ; DM de perfusion calculés ailleurs.")) -> Flacon/poudre : ajout par défaut 1 seringue + 1 aiguille ; à revalider selon présentation exacte. | Z30: =IF(A30="","",IF(ISNUMBER(SEARCH("Reconstitution",X30)),1,0)) -> 1 | AA30: =IF(Z30>0,"SERINGUE_PP_24ML","") -> SERINGUE_PP_24ML | AB30: =IF(Z30>0,Z30*VLOOKUP(AA30,FACTEURS_ITEMS!$A$3:$J$30,4,FALSE()),0) -> 0.069 | AC30: =IF(A30="","",IF(ISNUMBER(SEARCH("Reconstitution",X30)),1,0)) -> 1 | AD30: =IF(AC30>0,"AIGUILLE_RECONSTITUTION","") -> AIGUILLE_RECONSTITUTION | AE30: =IF(AC30>0,AC30*VLOOKUP(AD30,FACTEURS_ITEMS!$A$3:$J$30,4,FALSE()),0) -> 0.01 | AF30: =IF(A30="","",AB30+AE30) -> 0.079 | AG30: =IF(A30="","",S30+AF30) -> 0.262125 | AH30: =IF(A30="","",IF(AF30>0,"ACV médicament incluant PA + conditionnement + DM de reconstitution. Ne comprend pas poche/solvant/tubulure/administration.","ACV médicament sans DM de reconstitution ajouté.")) -> ACV médicament incluant PA + conditionnement + DM de reconstitution. Ne comprend pas poche/solvant/tubulure/administration.
A31: Aztréonam | B31: Flacon 2 g | C31: flacon verre | D31: Aztréonam | E31: 2000 | J31: =IFERROR(SUM(E31,G31,I31)/1000,"") -> 2 | K31: =$E$4 -> 100 | L31: =IF(J31="","",J31/1000*K31*(1+$E$5/100)) -> 0.21 | M31: =IF(J31="","",J31/1000*$E$6) -> 0.00019 | N31: =IF(C31="ampoule verre",$E$12,IF(C31="poche PEA",$E$13,$E$11)) -> 10 | O31: =IF(C31="ampoule verre",$E$8,IF(C31="poche PEA",$E$9,$E$7)) -> 7.1 | P31: =N31/1000*O31*(1+$E$5/100) -> 0.07455 | Q31: =$E$14 -> 3 | R31: =Q31/1000*$E$10 -> 0.00348 | S31: =IF(J31="","",SUM(L31:M31,P31,R31)) -> 0.28822 | T31: =IF(OR(J31="",K31=$E$4),"Élevé - FE PA générique",IF(W31<>"","À vérifier","Moyen")) -> Élevé - FE PA générique | U31: Breaking Stab | V31: EcovaMED v0.7 + hypothèses internes explicites | X31: =IF(A31="","",IF(OR(ISNUMBER(SEARCH("poche",C31)),ISNUMBER(SEARCH("ampoule",C31)),ISNUMBER(SEARCH("plastique",C31))),"Prêt à être dilué / administré (hypothèse)","Reconstitution nécessaire (hypothèse)")) -> Reconstitution nécessaire (hypothèse) | Y31: =IF(A31="","",IF(ISNUMBER(SEARCH("Reconstitution",X31)),"Flacon/poudre : ajout par défaut 1 seringue + 1 aiguille ; à revalider selon présentation exacte.","Ampoule/poche/présentation solution : aucun DM de reconstitution ajouté ; DM de perfusion calculés ailleurs.")) -> Flacon/poudre : ajout par défaut 1 seringue + 1 aiguille ; à revalider selon présentation exacte. | Z31: =IF(A31="","",IF(ISNUMBER(SEARCH("Reconstitution",X31)),1,0)) -> 1 | AA31: =IF(Z31>0,"SERINGUE_PP_24ML","") -> SERINGUE_PP_24ML | AB31: =IF(Z31>0,Z31*VLOOKUP(AA31,FACTEURS_ITEMS!$A$3:$J$30,4,FALSE()),0) -> 0.069 | AC31: =IF(A31="","",IF(ISNUMBER(SEARCH("Reconstitution",X31)),1,0)) -> 1 | AD31: =IF(AC31>0,"AIGUILLE_RECONSTITUTION","") -> AIGUILLE_RECONSTITUTION | AE31: =IF(AC31>0,AC31*VLOOKUP(AD31,FACTEURS_ITEMS!$A$3:$J$30,4,FALSE()),0) -> 0.01 | AF31: =IF(A31="","",AB31+AE31) -> 0.079 | AG31: =IF(A31="","",S31+AF31) -> 0.36722 | AH31: =IF(A31="","",IF(AF31>0,"ACV médicament incluant PA + conditionnement + DM de reconstitution. Ne comprend pas poche/solvant/tubulure/administration.","ACV médicament sans DM de reconstitution ajouté.")) -> ACV médicament incluant PA + conditionnement + DM de reconstitution. Ne comprend pas poche/solvant/tubulure/administration.
A32: Benzylpénicilline | B32: Flacon 1 MUI ≈ 0,6 g | C32: flacon verre | D32: Benzylpénicilline | E32: 600 | J32: =IFERROR(SUM(E32,G32,I32)/1000,"") -> 0.6 | K32: =$E$4 -> 100 | L32: =IF(J32="","",J32/1000*K32*(1+$E$5/100)) -> 0.063 | M32: =IF(J32="","",J32/1000*$E$6) -> 5.7e-05 | N32: =IF(C32="ampoule verre",$E$12,IF(C32="poche PEA",$E$13,$E$11)) -> 10 | O32: =IF(C32="ampoule verre",$E$8,IF(C32="poche PEA",$E$9,$E$7)) -> 7.1 | P32: =N32/1000*O32*(1+$E$5/100) -> 0.07455 | Q32: =$E$14 -> 3 | R32: =Q32/1000*$E$10 -> 0.00348 | S32: =IF(J32="","",SUM(L32:M32,P32,R32)) -> 0.141087 | T32: =IF(OR(J32="",K32=$E$4),"Élevé - FE PA générique",IF(W32<>"","À vérifier","Moyen")) -> Élevé - FE PA générique | U32: CHICAS/Breaking Stab ; conversion MUI approximative | V32: EcovaMED v0.7 + hypothèses internes explicites | W32: Conversion MUI→mg utilisée pour ordre de grandeur ; à confirmer avec la présentation locale. | X32: =IF(A32="","",IF(OR(ISNUMBER(SEARCH("poche",C32)),ISNUMBER(SEARCH("ampoule",C32)),ISNUMBER(SEARCH("plastique",C32))),"Prêt à être dilué / administré (hypothèse)","Reconstitution nécessaire (hypothèse)")) -> Reconstitution nécessaire (hypothèse) | Y32: =IF(A32="","",IF(ISNUMBER(SEARCH("Reconstitution",X32)),"Flacon/poudre : ajout par défaut 1 seringue + 1 aiguille ; à revalider selon présentation exacte.","Ampoule/poche/présentation solution : aucun DM de reconstitution ajouté ; DM de perfusion calculés ailleurs.")) -> Flacon/poudre : ajout par défaut 1 seringue + 1 aiguille ; à revalider selon présentation exacte. | Z32: =IF(A32="","",IF(ISNUMBER(SEARCH("Reconstitution",X32)),1,0)) -> 1 | AA32: =IF(Z32>0,"SERINGUE_PP_24ML","") -> SERINGUE_PP_24ML | AB32: =IF(Z32>0,Z32*VLOOKUP(AA32,FACTEURS_ITEMS!$A$3:$J$30,4,FALSE()),0) -> 0.069 | AC32: =IF(A32="","",IF(ISNUMBER(SEARCH("Reconstitution",X32)),1,0)) -> 1 | AD32: =IF(AC32>0,"AIGUILLE_RECONSTITUTION","") -> AIGUILLE_RECONSTITUTION | AE32: =IF(AC32>0,AC32*VLOOKUP(AD32,FACTEURS_ITEMS!$A$3:$J$30,4,FALSE()),0) -> 0.01 | AF32: =IF(A32="","",AB32+AE32) -> 0.079 | AG32: =IF(A32="","",S32+AF32) -> 0.220087 | AH32: =IF(A32="","",IF(AF32>0,"ACV médicament incluant PA + conditionnement + DM de reconstitution. Ne comprend pas poche/solvant/tubulure/administration.","ACV médicament sans DM de reconstitution ajouté.")) -> ACV médicament incluant PA + conditionnement + DM de reconstitution. Ne comprend pas poche/solvant/tubulure/administration.
